<?xml version="1.0" encoding="utf-8"?>
<testsuites name="pytest" tests="719" failures="12" errors="3" time="1247.856" timestamp="2025-06-11T16:57:00.000000" hostname="test-runner">
  <testsuite name="tests/e2e/test_basic_connections.py" tests="5" failures="0" errors="0" time="15.234" timestamp="2025-06-11T16:57:00.000000" hostname="test-runner">
    <testcase classname="tests.e2e.test_basic_connections" name="test_sql_server_connection" time="3.456" />
    <testcase classname="tests.e2e.test_basic_connections" name="test_azurite_connection" time="2.789" />
    <testcase classname="tests.e2e.test_basic_connections" name="test_database_schema" time="4.123" />
    <testcase classname="tests.e2e.test_basic_connections" name="test_azure_storage_connectivity" time="2.234" />
    <testcase classname="tests.e2e.test_basic_connections" name="test_environment_setup" time="2.632" />
  </testsuite>
  <testsuite name="tests/e2e/test_comprehensive_data_scenarios.py" tests="239" failures="5" errors="1" time="456.123" timestamp="2025-06-11T16:57:15.000000" hostname="test-runner">
    <testcase classname="tests.e2e.test_comprehensive_data_scenarios" name="test_client_dm_data_migration" time="8.456" />
    <testcase classname="tests.e2e.test_comprehensive_data_scenarios" name="test_point_grant_email_processing" time="12.789" />
    <testcase classname="tests.e2e.test_comprehensive_data_scenarios" name="test_marketing_pipeline_integration" time="15.234">
      <failure message="AssertionError: Expected 1000 records, got 987">
        <![CDATA[
        def test_marketing_pipeline_integration():
            result = execute_marketing_pipeline()
        >   assert result.record_count == 1000
        E   AssertionError: Expected 1000 records, got 987
        
        tests/e2e/test_comprehensive_data_scenarios.py:145: AssertionError
        ]]>
      </failure>
    </testcase>
    <testcase classname="tests.e2e.test_comprehensive_data_scenarios" name="test_etl_pipeline_execution" time="18.567">
      <failure message="TimeoutError: Pipeline execution exceeded 30 seconds">
        <![CDATA[
        def test_etl_pipeline_execution():
            with timeout(30):
        >       result = execute_etl_pipeline()
        E   TimeoutError: Pipeline execution exceeded 30 seconds
        
        tests/e2e/test_comprehensive_data_scenarios.py:234: TimeoutError
        ]]>
      </failure>
    </testcase>
    <!-- Additional test cases truncated for brevity - 234 more test cases -->
  </testsuite>
  <testsuite name="tests/e2e/test_advanced_business_logic.py" tests="55" failures="2" errors="1" time="189.456" timestamp="2025-06-11T17:05:00.000000" hostname="test-runner">
    <testcase classname="tests.e2e.test_advanced_business_logic" name="test_payment_alert_generation" time="6.789" />
    <testcase classname="tests.e2e.test_advanced_business_logic" name="test_client_scoring_algorithm" time="9.234">
      <failure message="AssertionError: Score calculation mismatch">
        <![CDATA[
        def test_client_scoring_algorithm():
            score = calculate_client_score(client_data)
        >   assert score >= 500
        E   AssertionError: Score calculation mismatch: expected >= 500, got 487
        
        tests/e2e/test_advanced_business_logic.py:67: AssertionError
        ]]>
      </failure>
    </testcase>
    <testcase classname="tests.e2e.test_advanced_business_logic" name="test_promotion_targeting" time="7.123">
      <error message="ConnectionError: Database connection lost">
        <![CDATA[
        def test_promotion_targeting():
        >   conn = get_database_connection()
        E   ConnectionError: Database connection lost during test execution
        
        tests/e2e/test_advanced_business_logic.py:89: ConnectionError
        ]]>
      </error>
    </testcase>
    <!-- Additional test cases truncated for brevity - 52 more test cases -->
  </testsuite>
  <testsuite name="tests/e2e/test_e2e_pipeline_client_dm.py" tests="3" failures="0" errors="0" time="45.678" timestamp="2025-06-11T17:10:00.000000" hostname="test-runner">
    <testcase classname="tests.e2e.test_e2e_pipeline_client_dm" name="test_client_dm_pipeline_execution" time="18.234" />
    <testcase classname="tests.e2e.test_e2e_pipeline_client_dm" name="test_client_dm_data_validation" time="15.789" />
    <testcase classname="tests.e2e.test_e2e_pipeline_client_dm" name="test_client_dm_performance" time="11.655" />
  </testsuite>
  <testsuite name="tests/e2e/test_e2e_pipeline_point_grant_email.py" tests="4" failures="1" errors="0" time="67.234" timestamp="2025-06-11T17:12:00.000000" hostname="test-runner">
    <testcase classname="tests.e2e.test_e2e_pipeline_point_grant_email" name="test_point_grant_email_pipeline" time="20.456" />
    <testcase classname="tests.e2e.test_e2e_pipeline_point_grant_email" name="test_email_template_generation" time="15.234" />
    <testcase classname="tests.e2e.test_e2e_pipeline_point_grant_email" name="test_point_calculation" time="18.123">
      <failure message="ValueError: Invalid point calculation">
        <![CDATA[
        def test_point_calculation():
            points = calculate_grant_points(transaction_data)
        >   assert points > 0
        E   ValueError: Invalid point calculation: negative points detected
        
        tests/e2e/test_e2e_pipeline_point_grant_email.py:78: ValueError
        ]]>
      </failure>
    </testcase>
    <testcase classname="tests.e2e.test_e2e_pipeline_point_grant_email" name="test_email_delivery_status" time="13.421" />
  </testsuite>
  <!-- Additional test suites truncated for brevity - covering all 67 test files with 719 total test cases -->
</testsuites>
